<?xml version="1.0" ?>
<!-- =================================================================================== -->
<!-- |    This document was autogenerated by xacro from ridgeback_omni.urdf.xacro      | -->
<!-- |    EDITING THIS FILE BY HAND IS NOT RECOMMENDED                                 | -->
<!-- =================================================================================== -->
<robot name="ridgebackur10e">
  <material name="dark_grey">
    <color rgba="0.2 0.2 0.2 1.0"/>
  </material>
  <material name="light_grey">
    <color rgba="0.4 0.4 0.4 1.0"/>
  </material>
  <material name="red">
    <color rgba="0.8 0.0 0.0 1.0"/>
  </material>
  <material name="white">
    <color rgba="0.9 0.9 0.9 1.0"/>
  </material>
  <material name="yellow">
    <color rgba="0.8 0.8 0.0 1.0"/>
  </material>
  <material name="black">
    <color rgba="0.15 0.15 0.15 1.0"/>
  </material>
  <link name="front_rocker_link">
    <visual>
      <origin rpy="1.5707963267948966 0 1.5707963267948966" xyz="0 0 0"/>
      <geometry>
        <mesh filename="description/ridgeback_description/meshes/rocker.stl"/>
      </geometry>
      <material name="black"/>
    </visual>
    <inertial>
      <origin rpy="1.5707963267948966 0 1.5707963267948966" xyz="0 0 0"/>
      <mass value="10.267"/>
      <inertia ixx="0.0288" ixy="2.20484e-6" ixz="-1.3145e-5" iyy="0.4324" iyz="1.8944e-3" izz="0.4130"/>
    </inertial>
  </link>
  <joint name="front_rocker" type="fixed">
    <parent link="axle_link"/>
    <child link="front_rocker_link"/>
    <origin rpy="0 0 0" xyz="0.319 0 0"/>
    <axis xyz="1 0 0"/>
    <limit effort="0" lower="-0.08726" upper="0.08726" velocity="0"/>
  </joint>
  <link name="front_left_wheel_link">
    <visual>
      <origin rpy="1.5707963267948966 0 0" xyz="0 0 0"/>
      <geometry>
        <mesh filename="description/ridgeback_description/meshes/wheel.stl"/>
      </geometry>
      <material name="black"/>
    </visual>
    <collision>
      <origin rpy="1.5707963267948966 0 0" xyz="0 0 0"/>
      <geometry>
        <cylinder length="0.079" radius="0.0759"/>
      </geometry>
    </collision>
    <inertial>
      <origin rpy="0 0 0" xyz="0 0 0"/>
      <mass value="2.3"/>
      <inertia ixx="3.3212e-3" ixy="0" ixz="0" iyy="6.6424e-3" iyz="0" izz="3.3212e-3"/>
    </inertial>
  </link>
  <joint name="front_left_wheel" type="fixed">
    <parent link="front_rocker_link"/>
    <child link="front_left_wheel_link"/>
    <origin rpy="0 0 0" xyz="0 0.27549999999999997 0"/>
    <axis xyz="0 1 0"/>
  </joint>
<!--  <transmission name="front_wheel_trans">-->
<!--    <type>transmission_interface/SimpleTransmission</type>-->
<!--    <joint name="front_left_wheel">-->
<!--      <hardwareInterface>hardware_interface/VelocityJointInterface</hardwareInterface>-->
<!--    </joint>-->
<!--    <actuator name="front_left_actuator">-->
<!--      <mechanicalReduction>1</mechanicalReduction>-->
<!--    </actuator>-->
<!--  </transmission>-->
  <link name="front_right_wheel_link">
    <visual>
      <origin rpy="1.5707963267948966 0 0" xyz="0 0 0"/>
      <geometry>
        <mesh filename="description/ridgeback_description/meshes/wheel.stl"/>
      </geometry>
      <material name="black"/>
    </visual>
    <collision>
      <origin rpy="1.5707963267948966 0 0" xyz="0 0 0"/>
      <geometry>
        <cylinder length="0.079" radius="0.0759"/>
      </geometry>
    </collision>
    <inertial>
      <origin rpy="0 0 0" xyz="0 0 0"/>
      <mass value="2.3"/>
      <inertia ixx="3.3212e-3" ixy="0" ixz="0" iyy="6.6424e-3" iyz="0" izz="3.3212e-3"/>
    </inertial>
  </link>
  <joint name="front_right_wheel" type="fixed">
    <parent link="front_rocker_link"/>
    <child link="front_right_wheel_link"/>
    <origin rpy="0 0 0" xyz="0 -0.27549999999999997 0"/>
    <axis xyz="0 1 0"/>
  </joint>
<!--  <transmission name="front_wheel_trans">-->
<!--    <type>transmission_interface/SimpleTransmission</type>-->
<!--    <joint name="front_right_wheel">-->
<!--      <hardwareInterface>hardware_interface/VelocityJointInterface</hardwareInterface>-->
<!--    </joint>-->
<!--    <actuator name="front_right_actuator">-->
<!--      <mechanicalReduction>1</mechanicalReduction>-->
<!--    </actuator>-->
<!--  </transmission>-->
  <link name="rear_rocker_link">
    <visual>
      <origin rpy="1.5707963267948966 0 1.5707963267948966" xyz="0 0 0"/>
      <geometry>
        <mesh filename="description/ridgeback_description/meshes/rocker.stl"/>
      </geometry>
      <material name="black"/>
    </visual>
    <inertial>
      <origin rpy="1.5707963267948966 0 1.5707963267948966" xyz="0 0 0"/>
      <mass value="10.267"/>
      <inertia ixx="0.0288" ixy="2.20484e-6" ixz="-1.3145e-5" iyy="0.4324" iyz="1.8944e-3" izz="0.4130"/>
    </inertial>
  </link>
  <joint name="rear_rocker" type="fixed">
    <parent link="axle_link"/>
    <child link="rear_rocker_link"/>
    <origin rpy="0 0 0" xyz="-0.319 0 0"/>
    <axis xyz="1 0 0"/>
    <limit effort="0" velocity="0"/>
  </joint>
  <link name="rear_left_wheel_link">
    <visual>
      <origin rpy="1.5707963267948966 0 0" xyz="0 0 0"/>
      <geometry>
        <mesh filename="description/ridgeback_description/meshes/wheel.stl"/>
      </geometry>
      <material name="black"/>
    </visual>
    <collision>
      <origin rpy="1.5707963267948966 0 0" xyz="0 0 0"/>
      <geometry>
        <cylinder length="0.079" radius="0.0759"/>
      </geometry>
    </collision>
    <inertial>
      <origin rpy="0 0 0" xyz="0 0 0"/>
      <mass value="2.3"/>
      <inertia ixx="3.3212e-3" ixy="0" ixz="0" iyy="6.6424e-3" iyz="0" izz="3.3212e-3"/>
    </inertial>
  </link>
  <joint name="rear_left_wheel" type="fixed">
    <parent link="rear_rocker_link"/>
    <child link="rear_left_wheel_link"/>
    <origin rpy="0 0 0" xyz="0 0.27549999999999997 0"/>
    <axis xyz="0 1 0"/>
  </joint>
<!--  <transmission name="rear_wheel_trans">-->
<!--    <type>transmission_interface/SimpleTransmission</type>-->
<!--    <joint name="rear_left_wheel">-->
<!--      <hardwareInterface>hardware_interface/VelocityJointInterface</hardwareInterface>-->
<!--    </joint>-->
<!--    <actuator name="rear_left_actuator">-->
<!--      <mechanicalReduction>1</mechanicalReduction>-->
<!--    </actuator>-->
<!--  </transmission>-->
  <link name="rear_right_wheel_link">
    <visual>
      <origin rpy="1.5707963267948966 0 0" xyz="0 0 0"/>
      <geometry>
        <mesh filename="description/ridgeback_description/meshes/wheel.stl"/>
      </geometry>
      <material name="black"/>
    </visual>
    <collision>
      <origin rpy="1.5707963267948966 0 0" xyz="0 0 0"/>
      <geometry>
        <cylinder length="0.079" radius="0.0759"/>
      </geometry>
    </collision>
    <inertial>
      <origin rpy="0 0 0" xyz="0 0 0"/>
      <mass value="2.3"/>
      <inertia ixx="3.3212e-3" ixy="0" ixz="0" iyy="6.6424e-3" iyz="0" izz="3.3212e-3"/>
    </inertial>
  </link>
  <joint name="rear_right_wheel" type="fixed">
    <parent link="rear_rocker_link"/>
    <child link="rear_right_wheel_link"/>
    <origin rpy="0 0 0" xyz="0 -0.27549999999999997 0"/>
    <axis xyz="0 1 0"/>
  </joint>
<!--  <transmission name="rear_wheel_trans">-->
<!--    <type>transmission_interface/SimpleTransmission</type>-->
<!--    <joint name="rear_right_wheel">-->
<!--      <hardwareInterface>hardware_interface/VelocityJointInterface</hardwareInterface>-->
<!--    </joint>-->
<!--    <actuator name="rear_right_actuator">-->
<!--      <mechanicalReduction>1</mechanicalReduction>-->
<!--    </actuator>-->
<!--  </transmission>-->
  <!--  <link name="base_link"></link>-->
  <!--  <joint name="base_link_joint" type="fixed">-->
  <!--    <origin xyz="0 0 0" rpy="0 0 0" />-->
  <!--    <parent link="base_link"/>-->
  <!--    <child link="chassis_link" />-->
  <!--  </joint>-->
  <link name="world_link"/>
  <link name="base_link_0"/>
  <link name="base_link_1"/>
  <joint name="x" type="prismatic">
    <limit effort="10000" lower="-5" upper="5" velocity="1.0"/>
    <parent link="world_link"/>
    <child link="base_link_0"/>
    <axis xyz="1 0 0"/>
  </joint>
  <joint name="y" type="prismatic">
    <limit effort="10000" lower="-5" upper="5" velocity="1.0"/>
    <parent link="base_link_0"/>
    <child link="base_link_1"/>
    <axis xyz="0 1 0"/>
  </joint>
  <joint name="theta" type="revolute"> <!--continuous-->
    <!-- <limit effort="10000" velocity="1.5708"/> -->
    <parent link="base_link_1"/>
    <child link="chassis_link"/>
    <axis xyz="0 0 1"/>
    <axis xyz="0 0 1"/>
    <limit effort="330.0" lower="-6.283185307179586" upper="6.283185307179586" velocity="2.0943951023931953"/>
  </joint>
  <link name="chassis_link">
    <visual>
      <origin rpy="0 0 0" xyz="0 0 0"/>
      <geometry>
        <mesh filename="description/ridgeback_description/meshes/body.stl"/>
      </geometry>
      <material name="black"/>
    </visual>
    <collision>
      <origin xyz="0 0 0"/>
      <geometry>
        <mesh filename="description/ridgeback_description/meshes/body-collision.stl"/>
      </geometry>
    </collision>
    <inertial>
      <origin rpy="1.5707963267948966 0 1.5707963267948966" xyz="0.012 0.002 0.067"/>
      <mass value="165.304"/>
      <inertia ixx="4.4744" ixy="0.03098" ixz="0.003647" iyy="7.1624" iyz="0.1228" izz="4.6155"/>
    </inertial>
  </link>
  <link name="riser_link">
    <visual>
      <origin rpy="0 0 0.7853981633974483" xyz="0 0 0.0275"/>
      <geometry>
        <box size="0.493 0.493 0.055"/>
      </geometry>
      <material name="light_grey"/>
    </visual>
    <collision>
      <origin rpy="0 0 0.7853981633974483" xyz="0 0 0.0275"/>
      <geometry>
        <box size="0.493 0.493 0.055"/>
      </geometry>
    </collision>
  </link>
  <joint name="riser_link_joint" type="fixed">
    <origin rpy="0 0 0" xyz="0 0 0.22"/>
    <parent link="chassis_link"/>
    <child link="riser_link"/>
  </joint>
  <joint name="right_side_cover_link_joint" type="fixed">
    <origin rpy="0 0 0" xyz="0 0 0"/>
    <parent link="chassis_link"/>
    <child link="right_side_cover_link"/>
  </joint>
  <joint name="left_side_cover_link_joint" type="fixed">
    <origin rpy="0 0 0" xyz="0 0 0"/>
    <parent link="chassis_link"/>
    <child link="left_side_cover_link"/>
  </joint>
  <link name="left_side_cover_link">
    <visual>
      <origin rpy="0 0 3.141592653589793" xyz="0 0 0"/>
      <geometry>
        <mesh filename="description/ridgeback_description/meshes/side-cover.stl"/>
      </geometry>
      <material name="yellow"/>
    </visual>
  </link>
  <link name="right_side_cover_link">
    <visual>
      <origin rpy="0 0 0" xyz="0 0 0"/>
      <geometry>
        <mesh filename="description/ridgeback_description/meshes/side-cover.stl"/>
      </geometry>
      <material name="yellow"/>
    </visual>
  </link>
  <joint name="front_cover_link_joint" type="fixed">
    <origin rpy="0 0 0" xyz="0 0 0"/>
    <parent link="chassis_link"/>
    <child link="front_cover_link"/>
  </joint>
  <link name="front_cover_link">
    <visual>
      <origin rpy="0 0 0" xyz="0 0 0"/>
      <geometry>
        <mesh filename="description/ridgeback_description/meshes/end-cover.stl"/>
      </geometry>
      <material name="black"/>
    </visual>
  </link>
  <joint name="rear_cover_link_joint" type="fixed">
    <origin rpy="0 0 0" xyz="0 0 0"/>
    <parent link="chassis_link"/>
    <child link="rear_cover_link"/>
  </joint>
  <link name="rear_cover_link">
    <visual>
      <origin rpy="0 0 3.141592653589793" xyz="0 0 0"/>
      <geometry>
        <mesh filename="description/ridgeback_description/meshes/end-cover.stl"/>
      </geometry>
      <material name="black"/>
    </visual>
  </link>
  <joint name="front_lights_link_joint" type="fixed">
    <origin rpy="0 0 0" xyz="0 0 0"/>
    <parent link="chassis_link"/>
    <child link="front_lights_link"/>
  </joint>
  <joint name="rear_lights_link_joint" type="fixed">
    <origin rpy="0 0 0" xyz="0 0 0"/>
    <parent link="chassis_link"/>
    <child link="rear_lights_link"/>
  </joint>
  <link name="front_lights_link">
    <visual>
      <origin rpy="0 0 0" xyz="0 0 0"/>
      <geometry>
        <mesh filename="description/ridgeback_description/meshes/lights.stl"/>
      </geometry>
      <material name="white"/>
    </visual>
  </link>
  <link name="rear_lights_link">
    <visual>
      <origin rpy="0 0 3.141592653589793" xyz="0 0 0"/>
      <geometry>
        <mesh filename="description/ridgeback_description/meshes/lights.stl"/>
      </geometry>
      <material name="black"/>
    </visual>
  </link>
  <joint name="top_link_joint" type="fixed">
    <origin rpy="0 0 0" xyz="0 0 -0.22000000000000003"/>
    <parent link="riser_link"/>
    <child link="top_link"/>
  </joint>
  <link name="top_link">
    <visual>
      <origin rpy="0 0 0" xyz="0 0 0"/>
      <geometry>
        <mesh filename="description/ridgeback_description/meshes/top.stl"/>
      </geometry>
      <material name="black"/>
    </visual>
    <collision>
      <origin rpy="0 0 0" xyz="0 0 0"/>
      <geometry>
        <mesh filename="description/ridgeback_description/meshes/top.stl"/>
      </geometry>
    </collision>
  </link>
  <joint name="axle_joint" type="fixed">
    <origin rpy="0 0 0" xyz="0 0 0.05"/>
    <parent link="chassis_link"/>
    <child link="axle_link"/>
  </joint>
  <link name="axle_link">
    <visual>
      <origin rpy="0 1.5707963267948966 0" xyz="0 0 0"/>
      <geometry>
        <mesh filename="description/ridgeback_description/meshes/axle.stl"/>
      </geometry>
      <material name="black"/>
    </visual>
  </link>
  <link name="imu_link">
    <inertial>
      <mass value="0.001"/>
      <origin rpy="0 0 0" xyz="0 0 0"/>
      <inertia ixx="1e-09" ixy="0.0" ixz="0.0" iyy="1e-09" iyz="0.0" izz="1e-09"/>
    </inertial>
  </link>
  <joint name="imu_joint" type="fixed">
    <parent link="chassis_link"/>
    <child link="imu_link"/>
    <origin rpy="0 0 0" xyz="0.2085 -0.2902 0.1681"/>
  </joint>
  <link name="mid_mount"/>
  <joint name="mid_mount_joint" type="fixed">
    <parent link="riser_link"/>
    <child link="mid_mount"/>
    <origin rpy="0 0 0" xyz="0 0 0.06"/>
  </joint>
  <gazebo>
    <plugin filename="libgazebo_ros_control.so" name="gazebo_ros_control">
      <robotNamespace>/</robotNamespace>
    </plugin>
    <plugin filename="libridgeback_ros_force_based_move.so" name="ridgeback_ros_force_based_move">
      <robotNamespace>/</robotNamespace>
      <commandTopic>cmd_vel</commandTopic>
      <odometryTopic>odom</odometryTopic>
      <odometryFrame>odom</odometryFrame>
      <odometryRate>25.0</odometryRate>
      <robotBaseFrame>base_link</robotBaseFrame>
      <cmdVelTimeOut>0.25</cmdVelTimeOut>
      <!-- Don't publish a transform: the controller does it. -->
      <publishOdometryTf>0</publishOdometryTf>
      <yaw_velocity_p_gain>500.0</yaw_velocity_p_gain>
      <x_velocity_p_gain>10000.0</x_velocity_p_gain>
      <y_velocity_p_gain>10000.0</y_velocity_p_gain>
    </plugin>
    <plugin filename="libhector_gazebo_ros_imu.so" name="imu_controller">
      <robotNamespace>/</robotNamespace>
      <updateRate>50.0</updateRate>
      <bodyName>imu_link</bodyName>
      <topicName>imu/data</topicName>
      <frameId>base_link</frameId>
      <accelDrift>0.005 0.005 0.005</accelDrift>
      <accelGaussianNoise>0.005 0.005 0.005</accelGaussianNoise>
      <rateDrift>0.00005 0.00005 0.00005</rateDrift>
      <rateGaussianNoise>0.00005 0.00005 0.00005</rateGaussianNoise>
      <headingDrift>0.005</headingDrift>
      <headingGaussianNoise>0.005</headingGaussianNoise>
    </plugin>
    <plugin filename="libgazebo_ros_joint_state_publisher.so" name="gazebo_ros_joint_state_publisher">
      <jointName>front_rocker</jointName>
      <robotNamespace>/</robotNamespace>
      <updateRate>50.0</updateRate>
    </plugin>
  </gazebo>
  <!-- All static links get collapsed down to base_link in Gazebo, so that's
       the one to apply the colour to (in Gazebo 5+). -->
  <gazebo reference="base_link">
    <material>Gazebo/DarkGrey</material>
    <gravity>true</gravity>
  </gazebo>
  <!-- Individual link colouring still needed in Gazebo 2.x -->
  <gazebo reference="chassis_link">
    <material>Gazebo/DarkGrey</material>
  </gazebo>
  <gazebo reference="top_link">
    <material>Gazebo/DarkGrey</material>
  </gazebo>
  <gazebo reference="left_side_cover_link">
    <material>Gazebo/Yellow</material>
  </gazebo>
  <gazebo reference="right_side_cover_link">
    <material>Gazebo/Yellow</material>
  </gazebo>
  <gazebo reference="front_cover_link">
    <material>Gazebo/DarkGrey</material>
  </gazebo>
  <gazebo reference="rear_cover_link">
    <material>Gazebo/DarkGrey</material>
  </gazebo>
  <gazebo reference="front_lights_link">
    <material>Gazebo/White</material>
  </gazebo>
  <gazebo reference="rear_lights_link">
    <material>Gazebo/Red</material>
  </gazebo>
  <gazebo reference="front_rocker_link">
    <material>Gazebo/DarkGrey</material>
  </gazebo>
  <gazebo reference="rear_rocker_link">
    <material>Gazebo/DarkGrey</material>
  </gazebo>
  <gazebo reference="axle_link">
    <material>Gazebo/DarkGrey</material>
  </gazebo>
  <!-- Wheel friction to zero, as movement is handled by applying forces at
       the body level. -->
  <gazebo reference="front_left_wheel_link">
    <material>Gazebo/DarkGrey</material>
    <mu1>0.0</mu1>
    <mu2>0.0</mu2>
  </gazebo>
  <gazebo reference="front_right_wheel_link">
    <material>Gazebo/DarkGrey</material>
    <mu1>0.0</mu1>
    <mu2>0.0</mu2>
  </gazebo>
  <gazebo reference="rear_left_wheel_link">
    <material>Gazebo/DarkGrey</material>
    <mu1>0.0</mu1>
    <mu2>0.0</mu2>
  </gazebo>
  <gazebo reference="rear_right_wheel_link">
    <material>Gazebo/DarkGrey</material>
    <mu1>0.0</mu1>
    <mu2>0.0</mu2>
  </gazebo>
  <!-- This is an wheel-level solution to possibly revisit at a future date. -->
  <!--<gazebo>
    <plugin name="mecanum_gazebo" filename="libmecanum_force_plugin.so">
      <wheelJointName>front_left_wheel</wheelJointName>
      <forceScaleFactor>1</forceScaleFactor>
    </plugin>
    <plugin name="mecanum_gazebo" filename="libmecanum_force_plugin.so">
      <wheelJointName>front_right_wheel</wheelJointName>
      <forceScaleFactor>-1</forceScaleFactor>
    </plugin>
    <plugin name="mecanum_gazebo" filename="libmecanum_force_plugin.so">
      <wheelJointName>rear_left_wheel</wheelJointName>
      <forceScaleFactor>-1</forceScaleFactor>
    </plugin>
    <plugin name="mecanum_gazebo" filename="libmecanum_force_plugin.so">
      <wheelJointName>rear_right_wheel</wheelJointName>
      <forceScaleFactor>1</forceScaleFactor>
    </plugin>
  </gazebo> -->
  <!--
    As you add to this URDF, please be aware that both the robot and
    simulation include it. You must retain compatibility with all of
    the following launch files:

    ridgeback_viz/launch/view_model.launch
    ridgeback_gazebo/launch/ridgeback_world.launch
    ridgeback_base/launch/base.launch
  -->
  <!-- UR ARM -->
  <!-- <xacro:include filename="$(find ridgeback_ur_description)/urdf/ridgeback_ur10_e_description.urdf.xacro" /> -->
  <!-- Color Reference (Existing)
  <material name="dark_grey"><color rgba="0.2 0.2 0.2 1.0" /></material>
  <material name="medium_grey"><color rgba="0.6 0.6 0.6 1.0" /></material>
  <material name="light_grey"><color rgba="0.8 0.8 0.8 1.0" /></material>
  <material name="yellow"><color rgba="0.8 0.8 0.0 1.0" /></material>
  <material name="black"><color rgba="0.15 0.15 0.15 1.0" /></material>
  <material name="white"><color rgba="1.0 1.0 1.0 1.0" /></material>
  <material name="red"><color rgba="1.0 0.0 0.0 1.0" /></material>
  -->
  <!-- Color Reference (Additional) -->
  <material name="blue">
    <color rgba="0.0 0.0 0.8 1.0"/>
  </material>
  <material name="green">
    <color rgba="0.0 0.8 0.0 1.0"/>
  </material>
  <material name="gray">
    <color rgba="0.7 0.7 0.7 1.0"/>
  </material>
  <!-- CMU57 Arch -->
  <link name="arch">
    <visual>
      <origin rpy="0 0 0" xyz="0 0 0"/>
      <material name="black"/>
      <geometry>
        <mesh filename="description/cmu57_description/meshes/cmu57_arch.STL"/>
      </geometry>
    </visual>
    <collision>
      <origin rpy="0 0 0" xyz="0 0 0"/>
      <geometry>
        <mesh filename="description/cmu57_description/meshes/cmu57_arch.STL"/>
      </geometry>
    </collision>
  </link>
  <joint name="arch_joint" type="fixed">
    <parent link="mid_mount"/>
    <child link="arch"/>
    <origin rpy="0 0 0" xyz="-0.22 0 0"/>
  </joint>
  <link name="front_camera_base_link">
    <visual>
      <geometry>
        <mesh filename="description/fath_pivot_mount_description/meshes/fath_pivot_mount_base.dae"/>
      </geometry>
      <origin rpy="0 0 1.5707963267948966" xyz="0 0 0"/>
    </visual>
    <collision>
      <geometry>
        <box size="0.025 0.025 0.03"/>
      </geometry>
      <origin rpy="0 0 0" xyz="0 0 0.015"/>
    </collision>
    <collision>
      <geometry>
        <cylinder length="0.03" radius="0.04"/>
      </geometry>
      <origin rpy="1.5707963267948966 0 0" xyz="0 -0.035 0.0225"/>
    </collision>
  </link>
  <link name="front_camera_hinge_link">
    <visual>
      <geometry>
        <mesh filename="description/fath_pivot_mount_description/meshes/fath_pivot_mount.dae"/>
      </geometry>
      <origin rpy="0 0 1.5707963267948966" xyz="0 0 0"/>
    </visual>
    <collision>
      <geometry>
        <box size="0.025 0.025 0.03"/>
      </geometry>
      <origin rpy="0 0 0" xyz="0 0 0.015"/>
    </collision>
  </link>
  <link name="front_camera_mount"/>
  <joint name="front_camera_base_joint" type="fixed">
    <parent link="mid_mount"/>
    <child link="front_camera_base_link"/>
    <origin rpy="0 0 3.1458" xyz=".45 0 0"/>
  </joint>
  <joint name="front_camera_hinge_joint" type="fixed">
    <parent link="front_camera_base_link"/>
    <child link="front_camera_hinge_link"/>
    <origin rpy="0 0 0" xyz="0 0 0.0225"/>
  </joint>
  <joint name="front_camera_mount_joint" type="fixed">
    <parent link="front_camera_hinge_link"/>
    <child link="front_camera_mount"/>
    <origin rpy="0 0 0" xyz="0 0 0.0225"/>
  </joint>
  <joint name="arm_mount_joint" type="fixed">
    <parent link="mid_mount"/>
    <child link="ur_arm_base_link"/>
    <origin rpy="0 0 3.1459" xyz="0.21 0.0 0.0"/>
  </joint>
  <!--
    Base UR robot series xacro macro.

    NOTE: this is NOT a URDF. It cannot directly be loaded by consumers
    expecting a flattened '.urdf' file. See the top-level '.xacro' for that
    (but note: that .xacro must still be processed by the xacro command).

    For use in '.launch' files: use one of the 'load_urX.launch' convenience
    launch files.

    This file models the base kinematic chain of a UR robot, which then gets
    parameterised by various configuration files to convert it into a UR3(e),
    UR5(e), UR10(e) or UR16e.

    NOTE: the default kinematic parameters (ie: link lengths, frame locations,
    offets, etc) do not correspond to any particular robot. They are defaults
    only. There WILL be non-zero offsets between the Forward Kinematics results
    in TF (ie: robot_state_publisher) and the values reported by the Teach
    Pendant.

    For accurate (and robot-specific) transforms, the 'kinematics_parameters_file'
    parameter MUST point to a .yaml file containing the appropriate values for
    the targetted robot.

    If using the UniversalRobots/Universal_Robots_ROS_Driver, follow the steps
    described in the readme of that repository to extract the kinematic
    calibration from the controller and generate the required .yaml file.

    Main author of the migration to yaml configs: Ludovic Delval.

    Contributors to previous versions (in no particular order):

     - Felix Messmer
     - Kelsey Hawkins
     - Wim Meeussen
     - Shaun Edwards
     - Nadia Hammoudeh Garcia
     - Dave Hershberger
     - G. vd. Hoorn
     - Philip Long
     - Dave Coleman
     - Miguel Prada
     - Mathias Luedtke
     - Marcel Schnirring
     - Felix von Drigalski
     - Felix Exner
     - Jimmy Da Silva
     - Ajit Krisshna N L
     - Muhammad Asif Rana
  -->
  <!--
    NOTE: the macro defined in this file is NOT part of the public API of this
          package. Users CANNOT rely on this file being available, or stored in
          this location. Nor can they rely on the existence of the macro.
  -->
<!--  <transmission name="ur_arm_shoulder_pan_trans">-->
<!--    <type>transmission_interface/SimpleTransmission</type>-->
<!--    <joint name="ur_arm_shoulder_pan_joint">-->
<!--      <hardwareInterface>hardware_interface/PositionJointInterface</hardwareInterface>-->
<!--    </joint>-->
<!--    <actuator name="ur_arm_shoulder_pan_motor">-->
<!--      <mechanicalReduction>1</mechanicalReduction>-->
<!--    </actuator>-->
<!--  </transmission>-->
<!--  <transmission name="ur_arm_shoulder_lift_trans">-->
<!--    <type>transmission_interface/SimpleTransmission</type>-->
<!--    <joint name="ur_arm_shoulder_lift_joint">-->
<!--      <hardwareInterface>hardware_interface/PositionJointInterface</hardwareInterface>-->
<!--    </joint>-->
<!--    <actuator name="ur_arm_shoulder_lift_motor">-->
<!--      <mechanicalReduction>1</mechanicalReduction>-->
<!--    </actuator>-->
<!--  </transmission>-->
<!--  <transmission name="ur_arm_elbow_trans">-->
<!--    <type>transmission_interface/SimpleTransmission</type>-->
<!--    <joint name="ur_arm_elbow_joint">-->
<!--      <hardwareInterface>hardware_interface/PositionJointInterface</hardwareInterface>-->
<!--    </joint>-->
<!--    <actuator name="ur_arm_elbow_motor">-->
<!--      <mechanicalReduction>1</mechanicalReduction>-->
<!--    </actuator>-->
<!--  </transmission>-->
<!--  <transmission name="ur_arm_wrist_1_trans">-->
<!--    <type>transmission_interface/SimpleTransmission</type>-->
<!--    <joint name="ur_arm_wrist_1_joint">-->
<!--      <hardwareInterface>hardware_interface/PositionJointInterface</hardwareInterface>-->
<!--    </joint>-->
<!--    <actuator name="ur_arm_wrist_1_motor">-->
<!--      <mechanicalReduction>1</mechanicalReduction>-->
<!--    </actuator>-->
<!--  </transmission>-->
<!--  <transmission name="ur_arm_wrist_2_trans">-->
<!--    <type>transmission_interface/SimpleTransmission</type>-->
<!--    <joint name="ur_arm_wrist_2_joint">-->
<!--      <hardwareInterface>hardware_interface/PositionJointInterface</hardwareInterface>-->
<!--    </joint>-->
<!--    <actuator name="ur_arm_wrist_2_motor">-->
<!--      <mechanicalReduction>1</mechanicalReduction>-->
<!--    </actuator>-->
<!--  </transmission>-->
<!--  <transmission name="ur_arm_wrist_3_trans">-->
<!--    <type>transmission_interface/SimpleTransmission</type>-->
<!--    <joint name="ur_arm_wrist_3_joint">-->
<!--      <hardwareInterface>hardware_interface/PositionJointInterface</hardwareInterface>-->
<!--    </joint>-->
<!--    <actuator name="ur_arm_wrist_3_motor">-->
<!--      <mechanicalReduction>1</mechanicalReduction>-->
<!--    </actuator>-->
<!--  </transmission>-->
  <!-- links: main serial chain -->
  <link name="ur_arm_base_link"/>
  <link name="ur_arm_base_link_inertia">
    <visual>
      <origin rpy="0 0 3.141592653589793" xyz="0 0 0"/>
      <geometry>
        <mesh filename="description/ur_description/meshes/ur10e/visual/base.dae"/>
      </geometry>
<!--      <material name="LightGrey">-->
<!--        <color rgba="0.7 0.7 0.7 1.0"/>-->
<!--      </material>-->
    </visual>
    <collision>
      <origin rpy="0 0 3.141592653589793" xyz="0 0 0"/>
      <geometry>
        <mesh filename="description/ur_description/meshes/ur10e/collision/base.stl"/>
      </geometry>
    </collision>
    <inertial>
      <mass value="4.0"/>
      <origin rpy="0 0 0" xyz="0 0 0"/>
      <inertia ixx="0.0061063308908" ixy="0.0" ixz="0.0" iyy="0.0061063308908" iyz="0.0" izz="0.01125"/>
    </inertial>
  </link>
  <link name="ur_arm_shoulder_link">
    <visual>
      <origin rpy="0 0 3.141592653589793" xyz="0 0 0"/>
      <geometry>
        <mesh filename="description/ur_description/meshes/ur10e/visual/shoulder.dae"/>
      </geometry>
<!--      <material name="LightGrey">-->
<!--        <color rgba="0.7 0.7 0.7 1.0"/>-->
<!--      </material>-->
    </visual>
    <collision>
      <origin rpy="0 0 3.141592653589793" xyz="0 0 0"/>
      <geometry>
        <mesh filename="description/ur_description/meshes/ur10e/collision/shoulder.stl"/>
      </geometry>
    </collision>
    <inertial>
      <mass value="7.778"/>
      <origin rpy="0 0 0" xyz="0 0 0"/>
      <inertia ixx="0.03147431257693659" ixy="0.0" ixz="0.0" iyy="0.03147431257693659" iyz="0.0" izz="0.021875624999999996"/>
    </inertial>
  </link>
  <link name="ur_arm_upper_arm_link">
    <visual>
      <origin rpy="1.5707963267948966 0 -1.5707963267948966" xyz="0 0 0.1762"/>
      <geometry>
        <mesh filename="description/ur_description/meshes/ur10e/visual/upperarm.dae"/>
      </geometry>
<!--      <material name="LightGrey">-->
<!--        <color rgba="0.7 0.7 0.7 1.0"/>-->
<!--      </material>-->
    </visual>
    <collision>
      <origin rpy="1.5707963267948966 0 -1.5707963267948966" xyz="0 0 0.1762"/>
      <geometry>
        <mesh filename="description/ur_description/meshes/ur10e/collision/upperarm.stl"/>
      </geometry>
    </collision>
    <inertial>
      <mass value="12.93"/>
      <origin rpy="0 1.5707963267948966 0" xyz="-0.306 0.0 0.175"/>
      <inertia ixx="0.42175380379841093" ixy="0.0" ixz="0.0" iyy="0.42175380379841093" iyz="0.0" izz="0.03636562499999999"/>
    </inertial>
  </link>
  <link name="ur_arm_forearm_link">
    <visual>
      <origin rpy="1.5707963267948966 0 -1.5707963267948966" xyz="0 0 0.0393"/>
      <geometry>
        <mesh filename="description/ur_description/meshes/ur10e/visual/forearm.dae"/>
      </geometry>
<!--      <material name="LightGrey">-->
<!--        <color rgba="0.7 0.7 0.7 1.0"/>-->
<!--      </material>-->
    </visual>
    <collision>
      <origin rpy="1.5707963267948966 0 -1.5707963267948966" xyz="0 0 0.0393"/>
      <geometry>
        <mesh filename="description/ur_description/meshes/ur10e/collision/forearm.stl"/>
      </geometry>
    </collision>
    <inertial>
      <mass value="3.87"/>
      <origin rpy="0 1.5707963267948966 0" xyz="-0.285775 0.0 0.0393"/>
      <inertia ixx="0.11079302548902206" ixy="0.0" ixz="0.0" iyy="0.11079302548902206" iyz="0.0" izz="0.010884375"/>
    </inertial>
  </link>
  <link name="ur_arm_wrist_1_link">
    <visual>
      <!-- TODO: Move this to a parameter -->
      <origin rpy="1.5707963267948966 0 0" xyz="0 0 -0.135"/>
      <geometry>
        <mesh filename="description/ur_description/meshes/ur10e/visual/wrist1.dae"/>
      </geometry>
<!--      <material name="LightGrey">-->
<!--        <color rgba="0.7 0.7 0.7 1.0"/>-->
<!--      </material>-->
    </visual>
    <collision>
      <origin rpy="1.5707963267948966 0 0" xyz="0 0 -0.135"/>
      <geometry>
        <mesh filename="description/ur_description/meshes/ur10e/collision/wrist1.stl"/>
      </geometry>
    </collision>
    <inertial>
      <mass value="1.96"/>
      <origin rpy="0 0 0" xyz="0 0 0"/>
      <inertia ixx="0.005108247956699999" ixy="0.0" ixz="0.0" iyy="0.005108247956699999" iyz="0.0" izz="0.005512499999999999"/>
    </inertial>
  </link>
  <link name="ur_arm_wrist_2_link">
    <visual>
      <origin rpy="0 0 0" xyz="0 0 -0.12"/>
      <geometry>
        <mesh filename="description/ur_description/meshes/ur10e/visual/wrist2.dae"/>
      </geometry>
<!--      <material name="LightGrey">-->
<!--        <color rgba="0.7 0.7 0.7 1.0"/>-->
<!--      </material>-->
    </visual>
    <collision>
      <origin rpy="0 0 0" xyz="0 0 -0.12"/>
      <geometry>
        <mesh filename="description/ur_description/meshes/ur10e/collision/wrist2.stl"/>
      </geometry>
    </collision>
    <inertial>
      <mass value="1.96"/>
      <origin rpy="0 0 0" xyz="0 0 0"/>
      <inertia ixx="0.005108247956699999" ixy="0.0" ixz="0.0" iyy="0.005108247956699999" iyz="0.0" izz="0.005512499999999999"/>
    </inertial>
  </link>
  <link name="ur_arm_wrist_3_link">
    <visual>
      <origin rpy="1.5707963267948966 0 0" xyz="0 0 -0.1168"/>
      <geometry>
        <mesh filename="description/ur_description/meshes/ur10e/visual/wrist3.dae"/>
      </geometry>
<!--      <material name="LightGrey">-->
<!--        <color rgba="0.7 0.7 0.7 1.0"/>-->
<!--      </material>-->
    </visual>
    <collision>
      <origin rpy="1.5707963267948966 0 0" xyz="0 0 -0.1168"/>
      <geometry>
        <mesh filename="description/ur_description/meshes/ur10e/collision/wrist3.stl"/>
      </geometry>
    </collision>
    <inertial>
      <mass value="0.202"/>
      <origin rpy="0 0 0" xyz="0.0 0.0 -0.025"/>
      <inertia ixx="0.00014434577559500002" ixy="0.0" ixz="0.0" iyy="0.00014434577559500002" iyz="0.0" izz="0.00020452500000000002"/>
    </inertial>
  </link>
  <!-- joints: main serial chain -->
  <joint name="ur_arm_base_link-base_link_inertia" type="fixed">
    <parent link="ur_arm_base_link"/>
    <child link="ur_arm_base_link_inertia"/>
    <!-- 'base_link' is REP-103 aligned (so X+ forward), while the internal
           frames of the robot/controller have X+ pointing backwards.
           Use the joint between 'base_link' and 'base_link_inertia' (a dummy
           link/frame) to introduce the necessary rotation over Z (of pi rad).
      -->
    <origin rpy="0 0 3.141592653589793" xyz="0 0 0"/>
  </joint>
  <joint name="ur_arm_shoulder_pan_joint" type="revolute">
    <parent link="ur_arm_base_link_inertia"/>
    <child link="ur_arm_shoulder_link"/>
    <origin rpy="0 0 0" xyz="0 0 0.1807"/>
    <axis xyz="0 0 1"/>
    <limit effort="330.0" lower="-6.283185307179586" upper="6.283185307179586" velocity="2.0943951023931953"/>
    <dynamics damping="0" friction="0"/>
  </joint>
  <joint name="ur_arm_shoulder_lift_joint" type="revolute">
    <parent link="ur_arm_shoulder_link"/>
    <child link="ur_arm_upper_arm_link"/>
    <origin rpy="1.570796327 0 0" xyz="0 0 0"/>
    <axis xyz="0 0 1"/>
    <limit effort="330.0" lower="-6.283185307179586" upper="6.283185307179586" velocity="2.0943951023931953"/>
    <dynamics damping="0" friction="0"/>
  </joint>
  <joint name="ur_arm_elbow_joint" type="revolute">
    <parent link="ur_arm_upper_arm_link"/>
    <child link="ur_arm_forearm_link"/>
    <origin rpy="0 0 0" xyz="-0.6127 0 0"/>
    <axis xyz="0 0 1"/>
    <limit effort="150.0" lower="-3.141592653589793" upper="3.141592653589793" velocity="3.141592653589793"/>
    <dynamics damping="0" friction="0"/>
  </joint>
  <joint name="ur_arm_wrist_1_joint" type="revolute">
    <parent link="ur_arm_forearm_link"/>
    <child link="ur_arm_wrist_1_link"/>
    <origin rpy="0 0 0" xyz="-0.57155 0 0.17415"/>
    <axis xyz="0 0 1"/>
    <limit effort="56.0" lower="-6.283185307179586" upper="6.283185307179586" velocity="3.141592653589793"/>
    <dynamics damping="0" friction="0"/>
  </joint>
  <joint name="ur_arm_wrist_2_joint" type="revolute">
    <parent link="ur_arm_wrist_1_link"/>
    <child link="ur_arm_wrist_2_link"/>
    <origin rpy="1.570796327 0 0" xyz="0 -0.11985 -2.458164590756244e-11"/>
    <axis xyz="0 0 1"/>
    <limit effort="56.0" lower="-6.283185307179586" upper="6.283185307179586" velocity="3.141592653589793"/>
    <dynamics damping="0" friction="0"/>
  </joint>
  <joint name="ur_arm_wrist_3_joint" type="revolute">
    <parent link="ur_arm_wrist_2_link"/>
    <child link="ur_arm_wrist_3_link"/>
    <origin rpy="1.570796326589793 3.141592653589793 3.141592653589793" xyz="0 0.11655 -2.390480459346185e-11"/>
    <axis xyz="0 0 1"/>
    <limit effort="56.0" lower="-6.283185307179586" upper="6.283185307179586" velocity="3.141592653589793"/>
    <dynamics damping="0" friction="0"/>
  </joint>
  <!-- ROS-Industrial 'base' frame: base_link to UR 'Base' Coordinates transform -->
  <link name="ur_arm_base"/>
  <joint name="ur_arm_base_link-base_fixed_joint" type="fixed">
    <!-- Note the rotation over Z of pi radians: as base_link is REP-103
           aligned (ie: has X+ forward, Y+ left and Z+ up), this is needed
           to correctly align 'base' with the 'Base' coordinate system of
           the UR controller.
      -->
    <origin rpy="0 0 3.141592653589793" xyz="0 0 0"/>
    <parent link="ur_arm_base_link"/>
    <child link="ur_arm_base"/>
  </joint>
  <!-- ROS-Industrial 'flange' frame: attachment point for EEF models -->
  <link name="ur_arm_flange"/>
  <joint name="ur_arm_wrist_3-flange" type="fixed">
    <parent link="ur_arm_wrist_3_link"/>
    <child link="ur_arm_flange"/>
    <origin rpy="0 -1.5707963267948966 -1.5707963267948966" xyz="0 0 0"/>
  </joint>
  <!-- ROS-Industrial 'tool0' frame: all-zeros tool frame -->
  <link name="ur_arm_tool0"/>
  <link name="ur_arm_TCP"/>
  <!-- end of link list -->
  <joint name="ur_arm_flange-tool0" type="fixed">
    <!-- default toolframe: X+ left, Y+ up, Z+ front -->
    <origin rpy="1.5707963267948966 0 1.5707963267948966" xyz="0 0 0"/>
    <parent link="ur_arm_flange"/>
    <child link="ur_arm_tool0"/>
  </joint>
  <joint name="ur_arm_tool0-TCP" type="fixed">
    <origin rpy="0 -3.141592653589793 1.5707963267948966" xyz="0 0 0.13"/>
    <parent link="ur_arm_tool0"/>
    <child link="ur_arm_TCP"/>
  </joint>
  <!-- UR Control Box -->
  <link name="ur_controlbox">
    <visual>
      <origin rpy="3.14 0 3.14" xyz="0 -0.07 0.17"/>
      <material name="light_grey"/>
      <geometry>
        <mesh filename="description/cmu57_description/meshes/urcontrolbox.STL"/>
      </geometry>
    </visual>
    <collision>
      <origin rpy="0 0 0" xyz="0 0 0.09"/>
      <geometry>
        <box size="0.45 0.2 0.18"/>
      </geometry>
    </collision>
  </link>
  <joint name="ur_controlbox_joint" type="fixed">
    <parent link="mid_mount"/>
    <child link="ur_controlbox"/>
    <origin rpy="0 0 0" xyz="-0.20 0 0"/>
  </joint>
  <link name="robotiq_arg2f_base_link">
    <inertial>
      <origin rpy="0 0 0" xyz="8.625E-08 -4.6583E-06 0.03145"/>
      <mass value="0.22652"/>
      <inertia ixx="0.00020005" ixy="-4.2442E-10" ixz="-2.9069E-10" iyy="0.00017832" iyz="-3.4402E-08" izz="0.00013478"/>
    </inertial>
    <visual>
      <origin rpy="0 0 0" xyz="0 0 0"/>
      <geometry>
        <mesh filename="description/robotiq_2f_85_gripper_visualization/meshes/visual/robotiq_arg2f_85_base_link.dae" scale="0.001 0.001 0.001"/>
      </geometry>
      <material name="">
        <color rgba="0.1 0.1 0.1 1"/>
      </material>
    </visual>
    <collision>
      <origin rpy="0 0 0" xyz="0 0 0"/>
      <geometry>
        <mesh filename="description/robotiq_2f_85_gripper_visualization/meshes/collision/robotiq_arg2f_base_link.stl"/>
      </geometry>
    </collision>
  </link>
  <link name="left_outer_knuckle">
    <!--<inertial>
        <origin xyz="-0.000200000000003065 0.0199435877845359 0.0292245259211331" rpy="0 0 0" />
        <mass value="0.00853198276973456" />
        <inertia ixx="2.89328108496468E-06" ixy="-1.57935047237397E-19" ixz="-1.93980378593255E-19" iyy="1.86719750325683E-06" iyz="-1.21858577871576E-06" izz="1.21905238907251E-06" />
        </inertial> -->
    <visual>
      <origin rpy="0 0 0" xyz="0 0 0"/>
      <geometry>
        <mesh filename="description/robotiq_2f_85_gripper_visualization/meshes/visual/robotiq_arg2f_85_outer_knuckle.dae" scale="0.001 0.001 0.001"/>
      </geometry>
      <material name="">
        <color rgba="0.792156862745098 0.819607843137255 0.933333333333333 1"/>
      </material>
    </visual>
    <collision>
      <origin rpy="0 0 0" xyz="0 0 0"/>
      <geometry>
        <mesh filename="description/robotiq_2f_85_gripper_visualization/meshes/collision/robotiq_arg2f_85_outer_knuckle.dae" scale="0.001 0.001 0.001"/>
      </geometry>
    </collision>
  </link>
  <link name="left_outer_finger">
    <!--<inertial>
        <origin xyz="0.00030115855001899 0.0373907951953854 -0.0208027427000385" rpy="0 0 0" />
        <mass value="0.022614240507152" />
        <inertia ixx="1.52518312458174E-05" ixy="9.76583423954399E-10" ixz="-5.43838577022588E-10" iyy="6.17694243867776E-06" iyz="6.78636130740228E-06" izz="1.16494917907219E-05" />
        </inertial> -->
    <visual>
      <origin rpy="0 0 0" xyz="0 0 0"/>
      <geometry>
        <mesh filename="description/robotiq_2f_85_gripper_visualization/meshes/visual/robotiq_arg2f_85_outer_finger.dae" scale="0.001 0.001 0.001"/>
      </geometry>
      <material name="">
        <color rgba="0.1 0.1 0.1 1"/>
      </material>
    </visual>
    <collision>
      <origin rpy="0 0 0" xyz="0 0 0"/>
      <geometry>
        <mesh filename="description/robotiq_2f_85_gripper_visualization/meshes/collision/robotiq_arg2f_85_outer_finger.dae" scale="0.001 0.001 0.001"/>
      </geometry>
    </collision>
  </link>
  <link name="left_inner_finger">
    <!--<inertial>
        <origin xyz="0.000299999999999317 0.0160078233491243 -0.0136945669206257" rpy="0 0 0" />
        <mass value="0.0104003125914103" />
        <inertia ixx="2.71909453810972E-06" ixy="1.35402465472579E-21" ixz="-7.1817349065269E-22" iyy="7.69100314106116E-07" iyz="6.74715432769696E-07" izz="2.30315190420171E-06" />
        </inertial> -->
    <visual>
      <origin rpy="0 0 0" xyz="0 0 0"/>
      <geometry>
        <mesh filename="description/robotiq_2f_85_gripper_visualization/meshes/visual/robotiq_arg2f_85_inner_finger.dae" scale="0.001 0.001 0.001"/>
      </geometry>
      <material name="">
        <color rgba="0.1 0.1 0.1 1"/>
      </material>
    </visual>
    <collision>
      <origin rpy="0 0 0" xyz="0 0 0"/>
      <geometry>
        <mesh filename="description/robotiq_2f_85_gripper_visualization/meshes/collision/robotiq_arg2f_85_inner_finger.dae" scale="0.001 0.001 0.001"/>
      </geometry>
    </collision>
  </link>
  <link name="left_inner_finger_pad">
    <visual>
      <origin rpy="0 0 0" xyz="0 0 0"/>
      <geometry>
        <box size="0.022 0.00635 0.0375"/>
      </geometry>
      <material name="">
        <color rgba="0.9 0.9 0.9 1"/>
      </material>
    </visual>
    <collision>
      <origin rpy="0 0 0" xyz="0 0 0"/>
      <geometry>
        <box size="0.022 0.00635 0.0375"/>
      </geometry>
      <material name="">
        <color rgba="0.9 0.0 0.0 1"/>
      </material>
    </collision>
  </link>
  <link name="left_inner_knuckle">
    <!--<inertial>
        <origin xyz="0.000123011831763771 0.0507850843201817 0.00103968640075166" rpy="0 0 0" />
       <mass value="0.0271177346495152" />
        <inertia ixx="2.61910379223783E-05" ixy="-2.43616858946494E-07" ixz="-6.37789906117123E-09" iyy="2.8270243746167E-06" iyz="-5.37200748039765E-07" izz="2.83695868220296E-05" />
        </inertial> -->
    <visual>
      <origin rpy="0 0 0" xyz="0 0 0"/>
      <geometry>
        <mesh filename="description/robotiq_2f_85_gripper_visualization/meshes/visual/robotiq_arg2f_85_inner_knuckle.dae" scale="0.001 0.001 0.001"/>
      </geometry>
      <material name="">
        <color rgba="0.1 0.1 0.1 1"/>
      </material>
    </visual>
    <collision>
      <origin rpy="0 0 0" xyz="0 0 0"/>
      <geometry>
        <mesh filename="description/robotiq_2f_85_gripper_visualization/meshes/collision/robotiq_arg2f_85_inner_knuckle.dae" scale="0.001 0.001 0.001"/>
      </geometry>
    </collision>
  </link>
  <link name="right_outer_knuckle">
    <!--<inertial>
        <origin xyz="-0.000200000000003065 0.0199435877845359 0.0292245259211331" rpy="0 0 0" />
        <mass value="0.00853198276973456" />
        <inertia ixx="2.89328108496468E-06" ixy="-1.57935047237397E-19" ixz="-1.93980378593255E-19" iyy="1.86719750325683E-06" iyz="-1.21858577871576E-06" izz="1.21905238907251E-06" />
        </inertial> -->
    <visual>
      <origin rpy="0 0 0" xyz="0 0 0"/>
      <geometry>
        <mesh filename="description/robotiq_2f_85_gripper_visualization/meshes/visual/robotiq_arg2f_85_outer_knuckle.dae" scale="0.001 0.001 0.001"/>
      </geometry>
      <material name="">
        <color rgba="0.792156862745098 0.819607843137255 0.933333333333333 1"/>
      </material>
    </visual>
    <collision>
      <origin rpy="0 0 0" xyz="0 0 0"/>
      <geometry>
        <mesh filename="description/robotiq_2f_85_gripper_visualization/meshes/collision/robotiq_arg2f_85_outer_knuckle.dae" scale="0.001 0.001 0.001"/>
      </geometry>
    </collision>
  </link>
  <link name="right_outer_finger">
    <!--<inertial>
        <origin xyz="0.00030115855001899 0.0373907951953854 -0.0208027427000385" rpy="0 0 0" />
        <mass value="0.022614240507152" />
        <inertia ixx="1.52518312458174E-05" ixy="9.76583423954399E-10" ixz="-5.43838577022588E-10" iyy="6.17694243867776E-06" iyz="6.78636130740228E-06" izz="1.16494917907219E-05" />
        </inertial> -->
    <visual>
      <origin rpy="0 0 0" xyz="0 0 0"/>
      <geometry>
        <mesh filename="description/robotiq_2f_85_gripper_visualization/meshes/visual/robotiq_arg2f_85_outer_finger.dae" scale="0.001 0.001 0.001"/>
      </geometry>
      <material name="">
        <color rgba="0.1 0.1 0.1 1"/>
      </material>
    </visual>
    <collision>
      <origin rpy="0 0 0" xyz="0 0 0"/>
      <geometry>
        <mesh filename="description/robotiq_2f_85_gripper_visualization/meshes/collision/robotiq_arg2f_85_outer_finger.dae" scale="0.001 0.001 0.001"/>
      </geometry>
    </collision>
  </link>
  <link name="right_inner_finger">
    <!--<inertial>
        <origin xyz="0.000299999999999317 0.0160078233491243 -0.0136945669206257" rpy="0 0 0" />
        <mass value="0.0104003125914103" />
        <inertia ixx="2.71909453810972E-06" ixy="1.35402465472579E-21" ixz="-7.1817349065269E-22" iyy="7.69100314106116E-07" iyz="6.74715432769696E-07" izz="2.30315190420171E-06" />
        </inertial> -->
    <visual>
      <origin rpy="0 0 0" xyz="0 0 0"/>
      <geometry>
        <mesh filename="description/robotiq_2f_85_gripper_visualization/meshes/visual/robotiq_arg2f_85_inner_finger.dae" scale="0.001 0.001 0.001"/>
      </geometry>
      <material name="">
        <color rgba="0.1 0.1 0.1 1"/>
      </material>
    </visual>
    <collision>
      <origin rpy="0 0 0" xyz="0 0 0"/>
      <geometry>
        <mesh filename="description/robotiq_2f_85_gripper_visualization/meshes/collision/robotiq_arg2f_85_inner_finger.dae" scale="0.001 0.001 0.001"/>
      </geometry>
    </collision>
  </link>
  <link name="right_inner_finger_pad">
    <visual>
      <origin rpy="0 0 0" xyz="0 0 0"/>
      <geometry>
        <box size="0.022 0.00635 0.0375"/>
      </geometry>
      <material name="">
        <color rgba="0.9 0.9 0.9 1"/>
      </material>
    </visual>
    <collision>
      <origin rpy="0 0 0" xyz="0 0 0"/>
      <geometry>
        <box size="0.022 0.00635 0.0375"/>
      </geometry>
      <material name="">
        <color rgba="0.9 0.0 0.0 1"/>
      </material>
    </collision>
  </link>
  <link name="right_inner_knuckle">
    <!--<inertial>
        <origin xyz="0.000123011831763771 0.0507850843201817 0.00103968640075166" rpy="0 0 0" />
       <mass value="0.0271177346495152" />
        <inertia ixx="2.61910379223783E-05" ixy="-2.43616858946494E-07" ixz="-6.37789906117123E-09" iyy="2.8270243746167E-06" iyz="-5.37200748039765E-07" izz="2.83695868220296E-05" />
        </inertial> -->
    <visual>
      <origin rpy="0 0 0" xyz="0 0 0"/>
      <geometry>
        <mesh filename="description/robotiq_2f_85_gripper_visualization/meshes/visual/robotiq_arg2f_85_inner_knuckle.dae" scale="0.001 0.001 0.001"/>
      </geometry>
      <material name="">
        <color rgba="0.1 0.1 0.1 1"/>
      </material>
    </visual>
    <collision>
      <origin rpy="0 0 0" xyz="0 0 0"/>
      <geometry>
        <mesh filename="description/robotiq_2f_85_gripper_visualization/meshes/collision/robotiq_arg2f_85_inner_knuckle.dae" scale="0.001 0.001 0.001"/>
      </geometry>
    </collision>
  </link>
  <joint name="left_outer_knuckle_joint" type="revolute">
    <origin rpy="0 0 3.141592653589793" xyz="0 -0.0306011 0.054904"/>
    <parent link="robotiq_arg2f_base_link"/>
    <child link="left_outer_knuckle"/>
    <axis xyz="1 0 0"/>
    <limit effort="1000" lower="0" upper="0.81" velocity="2.0"/>
  </joint>
  <joint name="left_outer_finger_joint" type="fixed">
    <origin rpy="0 0 0" xyz="0 0.0315 -0.0041"/>
    <parent link="left_outer_knuckle"/>
    <child link="left_outer_finger"/>
    <axis xyz="1 0 0"/>
  </joint>
  <joint name="left_inner_knuckle_joint" type="revolute">
    <!-- <origin xyz="0 ${reflect * -0.0127} 0.06142" rpy="${pi / 2 + .725} 0 ${(reflect - 1) * pi / 2}" /> -->
    <origin rpy="0 0 3.141592653589793" xyz="0 -0.0127 0.06142"/>
    <parent link="robotiq_arg2f_base_link"/>
    <child link="left_inner_knuckle"/>
    <axis xyz="1 0 0"/>
    <limit effort="1000" lower="0" upper="0.8757" velocity="2.0"/>
<!--    <mimic joint="left_outer_finger_joint" multiplier="1" offset="0"/>-->
  </joint>
  <joint name="left_inner_finger_joint" type="revolute">
    <origin rpy="0 0 0" xyz="0 0.0061 0.0471"/>
    <parent link="left_outer_finger"/>
    <child link="left_inner_finger"/>
    <axis xyz="1 0 0"/>
    <limit effort="1000" lower="-0.8757" upper="0" velocity="2.0"/>
<!--    <mimic joint="left_outer_finger_joint" multiplier="-1" offset="0"/>-->
  </joint>
  <joint name="left_inner_finger_pad_joint" type="fixed">
    <origin rpy="0 0 0" xyz="0 -0.0220203446692936 0.03242"/>
    <parent link="left_inner_finger"/>
    <child link="left_inner_finger_pad"/>
    <axis xyz="0 0 1"/>
  </joint>
  <joint name="right_outer_knuckle_joint" type="revolute">
    <origin rpy="0 0 0" xyz="0 0.0306011 0.054904"/>
    <parent link="robotiq_arg2f_base_link"/>
    <child link="right_outer_knuckle"/>
    <axis xyz="1 0 0"/>
    <limit effort="1000" lower="0" upper="0.81" velocity="2.0"/>
<!--    <mimic joint="finger_joint" multiplier="1" offset="0"/>-->
  </joint>
  <joint name="right_outer_finger_joint" type="fixed">
    <origin rpy="0 0 0" xyz="0 0.0315 -0.0041"/>
    <parent link="right_outer_knuckle"/>
    <child link="right_outer_finger"/>
    <axis xyz="1 0 0"/>
  </joint>
  <joint name="right_inner_knuckle_joint" type="revolute">
    <!-- <origin xyz="0 ${reflect * -0.0127} 0.06142" rpy="${pi / 2 + .725} 0 ${(reflect - 1) * pi / 2}" /> -->
    <origin rpy="0 0 0.0" xyz="0 0.0127 0.06142"/>
    <parent link="robotiq_arg2f_base_link"/>
    <child link="right_inner_knuckle"/>
    <axis xyz="1 0 0"/>
    <limit effort="1000" lower="0" upper="0.8757" velocity="2.0"/>
<!--    <mimic joint="finger_joint" multiplier="1" offset="0"/>-->
  </joint>
  <joint name="right_inner_finger_joint" type="revolute">
    <origin rpy="0 0 0" xyz="0 0.0061 0.0471"/>
    <parent link="right_outer_finger"/>
    <child link="right_inner_finger"/>
    <axis xyz="1 0 0"/>
    <limit effort="1000" lower="-0.8757" upper="0" velocity="2.0"/>
<!--    <mimic joint="finger_joint" multiplier="-1" offset="0"/>-->
  </joint>
  <joint name="right_inner_finger_pad_joint" type="fixed">
    <origin rpy="0 0 0" xyz="0 -0.0220203446692936 0.03242"/>
    <parent link="right_inner_finger"/>
    <child link="right_inner_finger_pad"/>
    <axis xyz="0 0 1"/>
  </joint>
<!--  <transmission name="finger_joint_trans">-->
<!--    <type>transmission_interface/SimpleTransmission</type>-->
<!--    <joint name="finger_joint">-->
<!--      <hardwareInterface>PositionJointInterface</hardwareInterface>-->
<!--    </joint>-->
<!--    <actuator name="finger_joint_motor">-->
<!--      <mechanicalReduction>1</mechanicalReduction>-->
<!--    </actuator>-->
<!--  </transmission>-->
  <joint name="robotiq_arg2f_joint" type="fixed">
    <parent link="ur_arm_tool0"/>
    <child link="robotiq_arg2f_base_link"/>
    <origin rpy="0 0 1.54" xyz="0 0 0"/>
  </joint>
  <!--xacro:robotiq_arg2f_85 prefix="gripper">
  </xacro:robotiq_arg2f_85-->
  <!--xacro:robotiq_2f_85_static prefix="gripper" parent="ur_arm_tool0">
    <origin xyz="0 0 0" rpy="0 0 3.1415" />
  </xacro:robotiq_2f_85_static-->
  <!-- Mimo Vue HD Touchscreen -->
  <link name="touchscreen">
    <visual>
      <origin rpy="1 0 -1.58" xyz="0 0 0"/>
      <material name="light_grey"/>
      <geometry>
        <mesh filename="description/cmu57_description/meshes/mimovuehd.STL"/>
      </geometry>
    </visual>
    <collision>
      <origin rpy="0 0 0" xyz="0 0 0"/>
      <geometry>
        <box size="0.18 0.28 0.22"/>
      </geometry>
    </collision>
  </link>
  <joint name="touchscreen_joint" type="fixed">
    <parent link="mid_mount"/>
    <child link="touchscreen"/>
    <origin rpy="0 0 0" xyz="-0.32 0 0.48"/>
  </joint>
  <!-- Autec Antenna -->
  <link name="autec_antenna">
    <visual>
      <origin rpy="1.58 0 0" xyz="0 0 0"/>
      <material name="black"/>
      <geometry>
        <mesh filename="description/cmu57_description/meshes/autecantenna.STL"/>
      </geometry>
    </visual>
    <collision>
      <origin rpy="0 0 0" xyz="0 0 0"/>
      <geometry>
        <cylinder length="0.1" radius="0.01"/>
      </geometry>
    </collision>
  </link>
  <joint name="autec_antenna_joint" type="fixed">
    <parent link="mid_mount"/>
    <child link="autec_antenna"/>
    <origin rpy="0 0 0" xyz="0.07 0.25 0"/>
  </joint>
  <!-- Wifi 1 Antenna -->
  <link name="wifi1_antenna">
    <visual>
      <origin rpy="0 1.58 0" xyz="0 0 0"/>
      <material name="black"/>
      <geometry>
        <mesh filename="description/cmu57_description/meshes/wifiantenna.STL"/>
      </geometry>
    </visual>
    <collision>
      <origin rpy="0 0 0" xyz="0 0 0"/>
      <geometry>
        <cylinder length="0.2" radius="0.01"/>
      </geometry>
    </collision>
  </link>
  <joint name="wifi1_antenna_joint" type="fixed">
    <parent link="mid_mount"/>
    <child link="wifi1_antenna"/>
    <origin rpy="0 0 0" xyz="-0.07 0.25 0"/>
  </joint>
  <!-- Wifi 2 Antenna -->
  <link name="wifi2_antenna">
    <visual>
      <origin rpy="0 1.58 0" xyz="0 0 0"/>
      <material name="black"/>
      <geometry>
        <mesh filename="description/cmu57_description/meshes/wifiantenna.STL"/>
      </geometry>
    </visual>
    <collision>
      <origin rpy="0 0 0" xyz="0 0 0"/>
      <geometry>
        <cylinder length="0.2" radius="0.01"/>
      </geometry>
    </collision>
  </link>
  <joint name="wifi2_antenna_joint" type="fixed">
    <parent link="mid_mount"/>
    <child link="wifi2_antenna"/>
    <origin rpy="0 0 0" xyz="-0.07 -0.25 0"/>
  </joint>
  <!-- This file is a placeholder which is included by default from
       ridgeback.urdf.xacro. If a robot is being customized and requires
       additional URDF, set the RIDGEBACK_URDF_EXTRAS environment variable
       to the full path of the file you would like included. -->
</robot>
